Workbook

Sheet Drivers
A1: Driver (edit/add here) | B1: Category | D1: Games (edit/add here)
A2: TomasRodri21 | B2: Human | D2: F1 25
A3: Polingua | B3: Human | D3: F1 24
A4: Fatacuida | B4: Human | D4: F1 23
A5: Lewis Hamilton | B5: F1 | D5: F1 22
A6: Max Verstappen | B6: F1 | D6: F1 2021
A7: Charles Leclerc | B7: F1 | D7: F1 2020
A8: Lando Norris | B8: F1 | D8: F1 2019
A9: George Russell | B9: F1
A10: Carlos Sainz Jr. | B10: F1
A11: Sergio Pérez | B11: F1
A12: Fernando Alonso | B12: F1
A13: Oscar Piastri | B13: F1
A14: Pierre Gasly | B14: F1
A15: Esteban Ocon | B15: F1
A16: Yuki Tsunoda | B16: F1
A17: Valtteri Bottas | B17: F1
A18: Nico Hülkenberg | B18: F1
A19: Lance Stroll | B19: F1
A20: Alexander Albon | B20: F1
... A38: Isack Hadjar | B38: F1

Sheet Teams
A1: Team (edit/add here)
A2: Mercedes
A3: Ferrari
A4: Red Bull Racing
A5: McLaren
A6: Renault
A7: Alpine
A8: Haas
A9: Racing Point
A10: Aston Martin
A11: Toro Rosso
A12: AlphaTauri
... A16: Williams

Sheet Seasons
A1: Season (edit/add here)
A2: 2019
A3: 2020
A4: 2021
A5: 2022
A6: 2023
A7: 2024
A8: 2025
A9: 2026
A10: 2027
A11: 2028
A12: 2029
A13: 2030

Sheet Leagues
A1: League Name (edit/add here)
A2: 100 por cento
A3: A Caminho do Tetra
A4: Classic League

Sheet GPs
A1: GP Name (edit/add here) | B1: Circuit
A2: Australian GP | B2: Albert Park Circuit
A3: Bahrain GP | B3: Bahrain International Circuit
A4: Saudi Arabian GP | B4: Jeddah Corniche Circuit
A5: Chinese GP | B5: Shanghai International Circuit
A6: Japanese GP | B6: Suzuka International Racing Course
A7: Emilia Romagna GP | B7: Autodromo Enzo e Dino Ferrari (Imola)
A8: Monaco GP | B8: Circuit de Monaco
A9: Canadian GP | B9: Circuit Gilles Villeneuve
A10: Spanish GP | B10: Circuit de Barcelona-Catalunya
A11: Austrian GP | B11: Red Bull Ring
A12: British GP | B12: Silverstone Circuit
... A33: Tuscan GP | B33: Mugello Circuit

Sheet PointsSystem
A1: Position | B1: Points
A2: 1 | B2: 25
A3: 2 | B3: 18
A4: 3 | B4: 15
A5: 4 | B5: 12
A6: 5 | B6: 10
A7: 6 | B7: 8
A8: 7 | B8: 6
A9: 8 | B9: 4
A10: 9 | B10: 2
A11: 10 | B11: 1
A12: 11 | B12: 0
A13: 12 | B13: 0
... A21: 20 | B21: 0

Sheet Races
A1: Game | B1: Season | C1: League Name | D1: Round | E1: GP Name | F1: Circuit (auto) | G1: Notes | H1: Key (hidden)
A2: F1 25 | B2: 2026 | C2: 100 por cento | D2: 1 | E2: British GP | F2: =IF(E2="","",IFERROR(VLOOKUP(E2,GPs!$A$2:$B$501,2,FALSE),"")) -> Silverstone Circuit | H2: =IF(OR(A2="",B2="",C2="",D2=""),"",A2&"|"&B2&"|"&C2&"|"&D2) -> F1 25|2026|100 por cento|1
A3: F1 25 | B3: 2026 | C3: 100 por cento | D3: 2 | E3: Belgian GP | F3: =IF(E3="","",IFERROR(VLOOKUP(E3,GPs!$A$2:$B$501,2,FALSE),"")) -> Circuit de Spa-Francorchamps | H3: =IF(OR(A3="",B3="",C3="",D3=""),"",A3&"|"&B3&"|"&C3&"|"&D3) -> F1 25|2026|100 por cento|2
A4: F1 25 | B4: 2026 | C4: 100 por cento | D4: 3 | E4: Japanese GP | F4: =IF(E4="","",IFERROR(VLOOKUP(E4,GPs!$A$2:$B$501,2,FALSE),"")) -> Suzuka International Racing Course | H4: =IF(OR(A4="",B4="",C4="",D4=""),"",A4&"|"&B4&"|"&C4&"|"&D4) -> F1 25|2026|100 por cento|3
A5: F1 25 | B5: 2026 | C5: 100 por cento | D5: 4 | E5: Bahrain GP | F5: =IF(E5="","",IFERROR(VLOOKUP(E5,GPs!$A$2:$B$501,2,FALSE),"")) -> Bahrain International Circuit | H5: =IF(OR(A5="",B5="",C5="",D5=""),"",A5&"|"&B5&"|"&C5&"|"&D5) -> F1 25|2026|100 por cento|4
A6: F1 25 | B6: 2026 | C6: 100 por cento | D6: 5 | E6: Saudi Arabian GP | F6: =IF(E6="","",IFERROR(VLOOKUP(E6,GPs!$A$2:$B$501,2,FALSE),"")) -> Jeddah Corniche Circuit | H6: =IF(OR(A6="",B6="",C6="",D6=""),"",A6&"|"&B6&"|"&C6&"|"&D6) -> F1 25|2026|100 por cento|5
A7: F1 25 | B7: 2026 | C7: 100 por cento | D7: 6 | E7: Miami GP | F7: =IF(E7="","",IFERROR(VLOOKUP(E7,GPs!$A$2:$B$501,2,FALSE),"")) -> Miami International Autodrome | H7: =IF(OR(A7="",B7="",C7="",D7=""),"",A7&"|"&B7&"|"&C7&"|"&D7) -> F1 25|2026|100 por cento|6
A8: F1 25 | B8: 2026 | C8: 100 por cento | D8: 7 | E8: Emilia Romagna GP | F8: =IF(E8="","",IFERROR(VLOOKUP(E8,GPs!$A$2:$B$501,2,FALSE),"")) -> Autodromo Enzo e Dino Ferrari (Imola) | H8: =IF(OR(A8="",B8="",C8="",D8=""),"",A8&"|"&B8&"|"&C8&"|"&D8) -> F1 25|2026|100 por cento|7
F9: =IF(E9="","",IFERROR(VLOOKUP(E9,GPs!$A$2:$B$501,2,FALSE),"")) | H9: =IF(OR(A9="",B9="",C9="",D9=""),"",A9&"|"&B9&"|"&C9&"|"&D9)
A10: F1 25 | B10: 2026 | C10: A Caminho do Tetra | D10: 1 | E10: Australian GP | F10: =IF(E10="","",IFERROR(VLOOKUP(E10,GPs!$A$2:$B$501,2,FALSE),"")) -> Albert Park Circuit | H10: =IF(OR(A10="",B10="",C10="",D10=""),"",A10&"|"&B10&"|"&C10&"|"&D10) -> F1 25|2026|A Caminho do Tetra|1
A11: F1 25 | B11: 2026 | C11: A Caminho do Tetra | D11: 2 | E11: Spanish GP | F11: =IF(E11="","",IFERROR(VLOOKUP(E11,GPs!$A$2:$B$501,2,FALSE),"")) -> Circuit de Barcelona-Catalunya | H11: =IF(OR(A11="",B11="",C11="",D11=""),"",A11&"|"&B11&"|"&C11&"|"&D11) -> F1 25|2026|A Caminho do Tetra|2
A12: F1 25 | B12: 2026 | C12: A Caminho do Tetra | D12: 3 | E12: Japanese GP | F12: =IF(E12="","",IFERROR(VLOOKUP(E12,GPs!$A$2:$B$501,2,FALSE),"")) -> Suzuka International Racing Course | H12: =IF(OR(A12="",B12="",C12="",D12=""),"",A12&"|"&B12&"|"&C12&"|"&D12) -> F1 25|2026|A Caminho do Tetra|3
A13: F1 25 | B13: 2026 | C13: A Caminho do Tetra | D13: 4 | E13: Bahrain GP | F13: =IF(E13="","",IFERROR(VLOOKUP(E13,GPs!$A$2:$B$501,2,FALSE),"")) -> Bahrain International Circuit | H13: =IF(OR(A13="",B13="",C13="",D13=""),"",A13&"|"&B13&"|"&C13&"|"&D13) -> F1 25|2026|A Caminho do Tetra|4
A14: F1 25 | B14: 2026 | C14: A Caminho do Tetra | D14: 5 | E14: Chinese GP | F14: =IF(E14="","",IFERROR(VLOOKUP(E14,GPs!$A$2:$B$501,2,FALSE),"")) -> Shanghai International Circuit | H14: =IF(OR(A14="",B14="",C14="",D14=""),"",A14&"|"&B14&"|"&C14&"|"&D14) -> F1 25|2026|A Caminho do Tetra|5
A15: F1 25 | B15: 2026 | C15: A Caminho do Tetra | D15: 6 | E15: Saudi Arabian GP | F15: =IF(E15="","",IFERROR(VLOOKUP(E15,GPs!$A$2:$B$501,2,FALSE),"")) -> Jeddah Corniche Circuit | H15: =IF(OR(A15="",B15="",C15="",D15=""),"",A15&"|"&B15&"|"&C15&"|"&D15) -> F1 25|2026|A Caminho do Tetra|6
A16: F1 25 | B16: 2026 | C16: A Caminho do Tetra | D16: 7 | E16: Miami GP | F16: =IF(E16="","",IFERROR(VLOOKUP(E16,GPs!$A$2:$B$501,2,FALSE),"")) -> Miami International Autodrome | H16: =IF(OR(A16="",B16="",C16="",D16=""),"",A16&"|"&B16&"|"&C16&"|"&D16) -> F1 25|2026|A Caminho do Tetra|7
A17: F1 25 | B17: 2026 | C17: A Caminho do Tetra | D17: 8 | E17: Las Vegas GP | F17: =IF(E17="","",IFERROR(VLOOKUP(E17,GPs!$A$2:$B$501,2,FALSE),"")) -> Las Vegas Strip Circuit | H17: =IF(OR(A17="",B17="",C17="",D17=""),"",A17&"|"&B17&"|"&C17&"|"&D17) -> F1 25|2026|A Caminho do Tetra|8
A18: F1 25 | B18: 2026 | C18: A Caminho do Tetra | D18: 9 | E18: Canadian GP | F18: =IF(E18="","",IFERROR(VLOOKUP(E18,GPs!$A$2:$B$501,2,FALSE),"")) -> Circuit Gilles Villeneuve | H18: =IF(OR(A18="",B18="",C18="",D18=""),"",A18&"|"&B18&"|"&C18&"|"&D18) -> F1 25|2026|A Caminho do Tetra|9
A19: F1 25 | B19: 2026 | C19: A Caminho do Tetra | D19: 10 | E19: United States GP | F19: =IF(E19="","",IFERROR(VLOOKUP(E19,GPs!$A$2:$B$501,2,FALSE),"")) -> Circuit of the Americas | H19: =IF(OR(A19="",B19="",C19="",D19=""),"",A19&"|"&B19&"|"&C19&"|"&D19) -> F1 25|2026|A Caminho do Tetra|10
A20: F1 25 | B20: 2026 | C20: A Caminho do Tetra | D20: 11 | E20: Qatar GP | F20: =IF(E20="","",IFERROR(VLOOKUP(E20,GPs!$A$2:$B$501,2,FALSE),"")) -> Lusail International Circuit | H20: =IF(OR(A20="",B20="",C20="",D20=""),"",A20&"|"&B20&"|"&C20&"|"&D20) -> F1 25|2026|A Caminho do Tetra|11
A21: F1 25 | B21: 2026 | C21: A Caminho do Tetra | D21: 12 | E21: Azerbaijan GP | F21: =IF(E21="","",IFERROR(VLOOKUP(E21,GPs!$A$2:$B$501,2,FALSE),"")) -> Baku City Circuit | H21: =IF(OR(A21="",B21="",C21="",D21=""),"",A21&"|"&B21&"|"&C21&"|"&D21) -> F1 25|2026|A Caminho do Tetra|12
A22: F1 25 | B22: 2026 | C22: A Caminho do Tetra | D22: 13 | E22: Emilia Romagna GP | F22: =IF(E22="","",IFERROR(VLOOKUP(E22,GPs!$A$2:$B$501,2,FALSE),"")) -> Autodromo Enzo e Dino Ferrari (Imola) | H22: =IF(OR(A22="",B22="",C22="",D22=""),"",A22&"|"&B22&"|"&C22&"|"&D22) -> F1 25|2026|A Caminho do Tetra|13
F23: =IF(E23="","",IFERROR(VLOOKUP(E23,GPs!$A$2:$B$501,2,FALSE),"")) | H23: =IF(OR(A23="",B23="",C23="",D23=""),"",A23&"|"&B23&"|"&C23&"|"&D23)
F24: =IF(E24="","",IFERROR(VLOOKUP(E24,GPs!$A$2:$B$501,2,FALSE),"")) | H24: =IF(OR(A24="",B24="",C24="",D24=""),"",A24&"|"&B24&"|"&C24&"|"&D24)
F25: =IF(E25="","",IFERROR(VLOOKUP(E25,GPs!$A$2:$B$501,2,FALSE),"")) | H25: =IF(OR(A25="",B25="",C25="",D25=""),"",A25&"|"&B25&"|"&C25&"|"&D25)
F26: =IF(E26="","",IFERROR(VLOOKUP(E26,GPs!$A$2:$B$501,2,FALSE),"")) | H26: =IF(OR(A26="",B26="",C26="",D26=""),"",A26&"|"&B26&"|"&C26&"|"&D26)
F27: =IF(E27="","",IFERROR(VLOOKUP(E27,GPs!$A$2:$B$501,2,FALSE),"")) | H27: =IF(OR(A27="",B27="",C27="",D27=""),"",A27&"|"&B27&"|"&C27&"|"&D27)
F28: =IF(E28="","",IFERROR(VLOOKUP(E28,GPs!$A$2:$B$501,2,FALSE),"")) | H28: =IF(OR(A28="",B28="",C28="",D28=""),"",A28&"|"&B28&"|"&C28&"|"&D28)
F29: =IF(E29="","",IFERROR(VLOOKUP(E29,GPs!$A$2:$B$501,2,FALSE),"")) | H29: =IF(OR(A29="",B29="",C29="",D29=""),"",A29&"|"&B29&"|"&C29&"|"&D29)
F30: =IF(E30="","",IFERROR(VLOOKUP(E30,GPs!$A$2:$B$501,2,FALSE),"")) | H30: =IF(OR(A30="",B30="",C30="",D30=""),"",A30&"|"&B30&"|"&C30&"|"&D30)
F31: =IF(E31="","",IFERROR(VLOOKUP(E31,GPs!$A$2:$B$501,2,FALSE),"")) | H31: =IF(OR(A31="",B31="",C31="",D31=""),"",A31&"|"&B31&"|"&C31&"|"&D31)
F32: =IF(E32="","",IFERROR(VLOOKUP(E32,GPs!$A$2:$B$501,2,FALSE),"")) | H32: =IF(OR(A32="",B32="",C32="",D32=""),"",A32&"|"&B32&"|"&C32&"|"&D32)
F33: =IF(E33="","",IFERROR(VLOOKUP(E33,GPs!$A$2:$B$501,2,FALSE),"")) | H33: =IF(OR(A33="",B33="",C33="",D33=""),"",A33&"|"&B33&"|"&C33&"|"&D33)
F34: =IF(E34="","",IFERROR(VLOOKUP(E34,GPs!$A$2:$B$501,2,FALSE),"")) | H34: =IF(OR(A34="",B34="",C34="",D34=""),"",A34&"|"&B34&"|"&C34&"|"&D34)
... F1000: =IF(E1000="","",IFERROR(VLOOKUP(E1000,GPs!$A$2:$B$501,2,FALSE),"")) | H1000: =IF(OR(A1000="",B1000="",C1000="",D1000=""),"",A1000&"|"&B1000&"|"&C1000&"|"&D1000)

Sheet PointsEntry
A1: Game | B1: Season | C1: League Name | D1: Round | E1: GP Name (auto) | F1: Driver | G1: Team | H1: Finish Pos | I1: Points (auto) | J1: Points Override | K1: Source
A2: F1 25 | B2: 2026 | C2: 100 por cento | D2: 1 | E2: =IF(OR(A2="",B2="",C2="",D2=""),"",IFERROR(INDEX(Races!$E$2:$E$1000,MATCH(A2&"|"&B2&"|"&C2&"|"&D2, Races!$H$2:$H$1000, 0)),"")) -> British GP | F2: Fatacuida | G2: Mercedes | H2: 1 | I2: =IF(H2="","",IF(J2<>"",J2,IFERROR(VLOOKUP(H2,PointsSystem!$A$2:$B$21,2,FALSE),0))) -> 25 | K2: Manual
A3: F1 25 | B3: 2026 | C3: 100 por cento | D3: 1 | E3: =IF(OR(A3="",B3="",C3="",D3=""),"",IFERROR(INDEX(Races!$E$2:$E$1000,MATCH(A3&"|"&B3&"|"&C3&"|"&D3, Races!$H$2:$H$1000, 0)),"")) -> British GP | F3: Fernando Alonso | G3: Aston Martin | H3: 2 | I3: =IF(H3="","",IF(J3<>"",J3,IFERROR(VLOOKUP(H3,PointsSystem!$A$2:$B$21,2,FALSE),0))) -> 18 | K3: Manual
A4: F1 25 | B4: 2026 | C4: 100 por cento | D4: 1 | E4: =IF(OR(A4="",B4="",C4="",D4=""),"",IFERROR(INDEX(Races!$E$2:$E$1000,MATCH(A4&"|"&B4&"|"&C4&"|"&D4, Races!$H$2:$H$1000, 0)),"")) -> British GP | F4: Gabriel Bortoleto | G4: Kick Sauber | H4: 3 | I4: =IF(H4="","",IF(J4<>"",J4,IFERROR(VLOOKUP(H4,PointsSystem!$A$2:$B$21,2,FALSE),0))) -> 15 | K4: Manual
A5: F1 25 | B5: 2026 | C5: 100 por cento | D5: 1 | E5: =IF(OR(A5="",B5="",C5="",D5=""),"",IFERROR(INDEX(Races!$E$2:$E$1000,MATCH(A5&"|"&B5&"|"&C5&"|"&D5, Races!$H$2:$H$1000, 0)),"")) -> British GP | F5: Carlos Sainz Jr. | G5: Williams | H5: 4 | I5: =IF(H5="","",IF(J5<>"",J5,IFERROR(VLOOKUP(H5,PointsSystem!$A$2:$B$21,2,FALSE),0))) -> 12 | K5: Manual
A6: F1 25 | B6: 2026 | C6: 100 por cento | D6: 1 | E6: =IF(OR(A6="",B6="",C6="",D6=""),"",IFERROR(INDEX(Races!$E$2:$E$1000,MATCH(A6&"|"&B6&"|"&C6&"|"&D6, Races!$H$2:$H$1000, 0)),"")) -> British GP | F6: Lando Norris | G6: McLaren | H6: 5 | I6: =IF(H6="","",IF(J6<>"",J6,IFERROR(VLOOKUP(H6,PointsSystem!$A$2:$B$21,2,FALSE),0))) -> 10
A7: F1 25 | B7: 2026 | C7: 100 por cento | D7: 1 | E7: =IF(OR(A7="",B7="",C7="",D7=""),"",IFERROR(INDEX(Races!$E$2:$E$1000,MATCH(A7&"|"&B7&"|"&C7&"|"&D7, Races!$H$2:$H$1000, 0)),"")) -> British GP | F7: Polingua | G7: Red Bull Racing | H7: 6 | I7: =IF(H7="","",IF(J7<>"",J7,IFERROR(VLOOKUP(H7,PointsSystem!$A$2:$B$21,2,FALSE),0))) -> 8
A8: F1 25 | B8: 2026 | C8: 100 por cento | D8: 1 | E8: =IF(OR(A8="",B8="",C8="",D8=""),"",IFERROR(INDEX(Races!$E$2:$E$1000,MATCH(A8&"|"&B8&"|"&C8&"|"&D8, Races!$H$2:$H$1000, 0)),"")) -> British GP | F8: George Russell | G8: Mercedes | H8: 7 | I8: =IF(H8="","",IF(J8<>"",J8,IFERROR(VLOOKUP(H8,PointsSystem!$A$2:$B$21,2,FALSE),0))) -> 6
A9: F1 25 | B9: 2026 | C9: 100 por cento | D9: 1 | E9: =IF(OR(A9="",B9="",C9="",D9=""),"",IFERROR(INDEX(Races!$E$2:$E$1000,MATCH(A9&"|"&B9&"|"&C9&"|"&D9, Races!$H$2:$H$1000, 0)),"")) -> British GP | F9: Oscar Piastri | G9: McLaren | H9: 8 | I9: =IF(H9="","",IF(J9<>"",J9,IFERROR(VLOOKUP(H9,PointsSystem!$A$2:$B$21,2,FALSE),0))) -> 4
A10: F1 25 | B10: 2026 | C10: 100 por cento | D10: 1 | E10: =IF(OR(A10="",B10="",C10="",D10=""),"",IFERROR(INDEX(Races!$E$2:$E$1000,MATCH(A10&"|"&B10&"|"&C10&"|"&D10, Races!$H$2:$H$1000, 0)),"")) -> British GP | F10: Pierre Gasly | G10: Alpine | H10: 9 | I10: =IF(H10="","",IF(J10<>"",J10,IFERROR(VLOOKUP(H10,PointsSystem!$A$2:$B$21,2,FALSE),0))) -> 2
A11: F1 25 | B11: 2026 | C11: 100 por cento | D11: 1 | E11: =IF(OR(A11="",B11="",C11="",D11=""),"",IFERROR(INDEX(Races!$E$2:$E$1000,MATCH(A11&"|"&B11&"|"&C11&"|"&D11, Races!$H$2:$H$1000, 0)),"")) -> British GP | F11: Nico Hülkenberg | G11: Kick Sauber | H11: 10 | I11: =IF(H11="","",IF(J11<>"",J11,IFERROR(VLOOKUP(H11,PointsSystem!$A$2:$B$21,2,FALSE),0))) -> 1
A12: F1 25 | B12: 2026 | C12: 100 por cento | D12: 1 | E12: =IF(OR(A12="",B12="",C12="",D12=""),"",IFERROR(INDEX(Races!$E$2:$E$1000,MATCH(A12&"|"&B12&"|"&C12&"|"&D12, Races!$H$2:$H$1000, 0)),"")) -> British GP | F12: Max Verstappen | G12: Red Bull Racing | H12: 11 | I12: =IF(H12="","",IF(J12<>"",J12,IFERROR(VLOOKUP(H12,PointsSystem!$A$2:$B$21,2,FALSE),0))) -> 0
A13: F1 25 | B13: 2026 | C13: 100 por cento | D13: 1 | E13: =IF(OR(A13="",B13="",C13="",D13=""),"",IFERROR(INDEX(Races!$E$2:$E$1000,MATCH(A13&"|"&B13&"|"&C13&"|"&D13, Races!$H$2:$H$1000, 0)),"")) -> British GP | F13: Charles Leclerc | G13: Ferrari | H13: 12 | I13: =IF(H13="","",IF(J13<>"",J13,IFERROR(VLOOKUP(H13,PointsSystem!$A$2:$B$21,2,FALSE),0))) -> 0
A14: F1 25 | B14: 2026 | C14: 100 por cento | D14: 1 | E14: =IF(OR(A14="",B14="",C14="",D14=""),"",IFERROR(INDEX(Races!$E$2:$E$1000,MATCH(A14&"|"&B14&"|"&C14&"|"&D14, Races!$H$2:$H$1000, 0)),"")) -> British GP | F14: Liam Lawson | G14: RB (Racing Bulls) | H14: 13 | I14: =IF(H14="","",IF(J14<>"",J14,IFERROR(VLOOKUP(H14,PointsSystem!$A$2:$B$21,2,FALSE),0))) -> 0
A15: F1 25 | B15: 2026 | C15: 100 por cento | D15: 1 | E15: =IF(OR(A15="",B15="",C15="",D15=""),"",IFERROR(INDEX(Races!$E$2:$E$1000,MATCH(A15&"|"&B15&"|"&C15&"|"&D15, Races!$H$2:$H$1000, 0)),"")) -> British GP | F15: Oliver Bearman | G15: Haas | H15: 14 | I15: =IF(H15="","",IF(J15<>"",J15,IFERROR(VLOOKUP(H15,PointsSystem!$A$2:$B$21,2,FALSE),0))) -> 0
A16: F1 25 | B16: 2026 | C16: 100 por cento | D16: 1 | E16: =IF(OR(A16="",B16="",C16="",D16=""),"",IFERROR(INDEX(Races!$E$2:$E$1000,MATCH(A16&"|"&B16&"|"&C16&"|"&D16, Races!$H$2:$H$1000, 0)),"")) -> British GP | F16: Lance Stroll | G16: Aston Martin | H16: 15 | I16: =IF(H16="","",IF(J16<>"",J16,IFERROR(VLOOKUP(H16,PointsSystem!$A$2:$B$21,2,FALSE),0))) -> 0
A17: F1 25 | B17: 2026 | C17: 100 por cento | D17: 1 | E17: =IF(OR(A17="",B17="",C17="",D17=""),"",IFERROR(INDEX(Races!$E$2:$E$1000,MATCH(A17&"|"&B17&"|"&C17&"|"&D17, Races!$H$2:$H$1000, 0)),"")) -> British GP | F17: Isack Hadjar | G17: RB (Racing Bulls) | H17: 16 | I17: =IF(H17="","",IF(J17<>"",J17,IFERROR(VLOOKUP(H17,PointsSystem!$A$2:$B$21,2,FALSE),0))) -> 0
... A141: F1 25 | B141: 2026 | C141: 100 por cento | D141: 7 | E141: =IF(OR(A141="",B141="",C141="",D141=""),"",IFERROR(INDEX(Races!$E$2:$E$1000,MATCH(A141&"|"&B141&"|"&C141&"|"&D141, Races!$H$2:$H$1000, 0)),"")) -> Emilia Romagna GP | F141: Oliver Bearman | G141: Haas | H141: 20 | I141: =IF(H141="","",IF(J141<>"",J141,IFERROR(VLOOKUP(H141,PointsSystem!$A$2:$B$21,2,FALSE),0))) -> 0
E142: =IF(OR(A142="",B142="",C142="",D142=""),"",IFERROR(INDEX(Races!$E$2:$E$1000,MATCH(A142&"|"&B142&"|"&C142&"|"&D142, Races!$H$2:$H$1000, 0)),"")) | I142: =IF(H142="","",IF(J142<>"",J142,IFERROR(VLOOKUP(H142,PointsSystem!$A$2:$B$21,2,FALSE),0)))
A143: F1 25 | B143: 2026 | C143: A Caminho do Tetra | D143: 1 | E143: =IF(OR(A143="",B143="",C143="",D143=""),"",IFERROR(INDEX(Races!$E$2:$E$1000,MATCH(A143&"|"&B143&"|"&C143&"|"&D143, Races!$H$2:$H$1000, 0)),"")) -> Australian GP | F143: TomasRodri21 | G143: Aston Martin | H143: 1 | I143: =IF(H143="","",IF(J143<>"",J143,IFERROR(VLOOKUP(H143,PointsSystem!$A$2:$B$21,2,FALSE),0))) -> 25
A144: F1 25 | B144: 2026 | C144: A Caminho do Tetra | D144: 1 | E144: =IF(OR(A144="",B144="",C144="",D144=""),"",IFERROR(INDEX(Races!$E$2:$E$1000,MATCH(A144&"|"&B144&"|"&C144&"|"&D144, Races!$H$2:$H$1000, 0)),"")) -> Australian GP | F144: Oscar Piastri | G144: McLaren | H144: 2 | I144: =IF(H144="","",IF(J144<>"",J144,IFERROR(VLOOKUP(H144,PointsSystem!$A$2:$B$21,2,FALSE),0))) -> 18
A145: F1 25 | B145: 2026 | C145: A Caminho do Tetra | D145: 1 | E145: =IF(OR(A145="",B145="",C145="",D145=""),"",IFERROR(INDEX(Races!$E$2:$E$1000,MATCH(A145&"|"&B145&"|"&C145&"|"&D145, Races!$H$2:$H$1000, 0)),"")) -> Australian GP | F145: Polingua | G145: Kick Sauber | H145: 3 | I145: =IF(H145="","",IF(J145<>"",J145,IFERROR(VLOOKUP(H145,PointsSystem!$A$2:$B$21,2,FALSE),0))) -> 15
A146: F1 25 | B146: 2026 | C146: A Caminho do Tetra | D146: 1 | E146: =IF(OR(A146="",B146="",C146="",D146=""),"",IFERROR(INDEX(Races!$E$2:$E$1000,MATCH(A146&"|"&B146&"|"&C146&"|"&D146, Races!$H$2:$H$1000, 0)),"")) -> Australian GP | F146: Charles Leclerc | G146: Ferrari | H146: 4 | I146: =IF(H146="","",IF(J146<>"",J146,IFERROR(VLOOKUP(H146,PointsSystem!$A$2:$B$21,2,FALSE),0))) -> 12
A147: F1 25 | B147: 2026 | C147: A Caminho do Tetra | D147: 1 | E147: =IF(OR(A147="",B147="",C147="",D147=""),"",IFERROR(INDEX(Races!$E$2:$E$1000,MATCH(A147&"|"&B147&"|"&C147&"|"&D147, Races!$H$2:$H$1000, 0)),"")) -> Australian GP | F147: George Russell | G147: Mercedes | H147: 5 | I147: =IF(H147="","",IF(J147<>"",J147,IFERROR(VLOOKUP(H147,PointsSystem!$A$2:$B$21,2,FALSE),0))) -> 10
A148: F1 25 | B148: 2026 | C148: A Caminho do Tetra | D148: 1 | E148: =IF(OR(A148="",B148="",C148="",D148=""),"",IFERROR(INDEX(Races!$E$2:$E$1000,MATCH(A148&"|"&B148&"|"&C148&"|"&D148, Races!$H$2:$H$1000, 0)),"")) -> Australian GP | F148: Yuki Tsunoda | G148: Red Bull Racing | H148: 6 | I148: =IF(H148="","",IF(J148<>"",J148,IFERROR(VLOOKUP(H148,PointsSystem!$A$2:$B$21,2,FALSE),0))) -> 8
A149: F1 25 | B149: 2026 | C149: A Caminho do Tetra | D149: 1 | E149: =IF(OR(A149="",B149="",C149="",D149=""),"",IFERROR(INDEX(Races!$E$2:$E$1000,MATCH(A149&"|"&B149&"|"&C149&"|"&D149, Races!$H$2:$H$1000, 0)),"")) -> Australian GP | F149: Andrea Kimi Antonelli | G149: Mercedes | H149: 7 | I149: =IF(H149="","",IF(J149<>"",J149,IFERROR(VLOOKUP(H149,PointsSystem!$A$2:$B$21,2,FALSE),0))) -> 6
A150: F1 25 | B150: 2026 | C150: A Caminho do Tetra | D150: 1 | E150: =IF(OR(A150="",B150="",C150="",D150=""),"",IFERROR(INDEX(Races!$E$2:$E$1000,MATCH(A150&"|"&B150&"|"&C150&"|"&D150, Races!$H$2:$H$1000, 0)),"")) -> Australian GP | F150: Max Verstappen | G150: Red Bull Racing | H150: 8 | I150: =IF(H150="","",IF(J150<>"",J150,IFERROR(VLOOKUP(H150,PointsSystem!$A$2:$B$21,2,FALSE),0))) -> 4
A151: F1 25 | B151: 2026 | C151: A Caminho do Tetra | D151: 1 | E151: =IF(OR(A151="",B151="",C151="",D151=""),"",IFERROR(INDEX(Races!$E$2:$E$1000,MATCH(A151&"|"&B151&"|"&C151&"|"&D151, Races!$H$2:$H$1000, 0)),"")) -> Australian GP | F151: Alexander Albon | G151: Williams | H151: 9 | I151: =IF(H151="","",IF(J151<>"",J151,IFERROR(VLOOKUP(H151,PointsSystem!$A$2:$B$21,2,FALSE),0))) -> 2
A152: F1 25 | B152: 2026 | C152: A Caminho do Tetra | D152: 1 | E152: =IF(OR(A152="",B152="",C152="",D152=""),"",IFERROR(INDEX(Races!$E$2:$E$1000,MATCH(A152&"|"&B152&"|"&C152&"|"&D152, Races!$H$2:$H$1000, 0)),"")) -> Australian GP | F152: Fernando Alonso | G152: Aston Martin | H152: 10 | I152: =IF(H152="","",IF(J152<>"",J152,IFERROR(VLOOKUP(H152,PointsSystem!$A$2:$B$21,2,FALSE),0))) -> 1
A153: F1 25 | B153: 2026 | C153: A Caminho do Tetra | D153: 1 | E153: =IF(OR(A153="",B153="",C153="",D153=""),"",IFERROR(INDEX(Races!$E$2:$E$1000,MATCH(A153&"|"&B153&"|"&C153&"|"&D153, Races!$H$2:$H$1000, 0)),"")) -> Australian GP | F153: Nico Hülkenberg | G153: Kick Sauber | H153: 11 | I153: =IF(H153="","",IF(J153<>"",J153,IFERROR(VLOOKUP(H153,PointsSystem!$A$2:$B$21,2,FALSE),0))) -> 0
A154: F1 25 | B154: 2026 | C154: A Caminho do Tetra | D154: 1 | E154: =IF(OR(A154="",B154="",C154="",D154=""),"",IFERROR(INDEX(Races!$E$2:$E$1000,MATCH(A154&"|"&B154&"|"&C154&"|"&D154, Races!$H$2:$H$1000, 0)),"")) -> Australian GP | F154: Fatacuida | G154: Haas | H154: 12 | I154: =IF(H154="","",IF(J154<>"",J154,IFERROR(VLOOKUP(H154,PointsSystem!$A$2:$B$21,2,FALSE),0))) -> 0
... A342: F1 25 | B342: 2026 | C342: A Caminho do Tetra | D342: 10 | E342: =IF(OR(A342="",B342="",C342="",D342=""),"",IFERROR(INDEX(Races!$E$2:$E$1000,MATCH(A342&"|"&B342&"|"&C342&"|"&D342, Races!$H$2:$H$1000, 0)),"")) -> United States GP | F342: Nico Hülkenberg | G342: Kick Sauber | H342: 20 | I342: =IF(H342="","",IF(J342<>"",J342,IFERROR(VLOOKUP(H342,PointsSystem!$A$2:$B$21,2,FALSE),0))) -> 0
A343: F1 25 | B343: 2026 | C343: A Caminho do Tetra | D343: 11 | E343: =IF(OR(A343="",B343="",C343="",D343=""),"",IFERROR(INDEX(Races!$E$2:$E$1000,MATCH(A343&"|"&B343&"|"&C343&"|"&D343, Races!$H$2:$H$1000, 0)),"")) -> Qatar GP | H343: 1 | I343: =IF(H343="","",IF(J343<>"",J343,IFERROR(VLOOKUP(H343,PointsSystem!$A$2:$B$21,2,FALSE),0))) -> 25
E344: =IF(OR(A344="",B344="",C344="",D344=""),"",IFERROR(INDEX(Races!$E$2:$E$1000,MATCH(A344&"|"&B344&"|"&C344&"|"&D344, Races!$H$2:$H$1000, 0)),"")) | H344: 2 | I344: =IF(H344="","",IF(J344<>"",J344,IFERROR(VLOOKUP(H344,PointsSystem!$A$2:$B$21,2,FALSE),0))) -> 18
E345: =IF(OR(A345="",B345="",C345="",D345=""),"",IFERROR(INDEX(Races!$E$2:$E$1000,MATCH(A345&"|"&B345&"|"&C345&"|"&D345, Races!$H$2:$H$1000, 0)),"")) | H345: 3 | I345: =IF(H345="","",IF(J345<>"",J345,IFERROR(VLOOKUP(H345,PointsSystem!$A$2:$B$21,2,FALSE),0))) -> 15
E346: =IF(OR(A346="",B346="",C346="",D346=""),"",IFERROR(INDEX(Races!$E$2:$E$1000,MATCH(A346&"|"&B346&"|"&C346&"|"&D346, Races!$H$2:$H$1000, 0)),"")) | H346: 4 | I346: =IF(H346="","",IF(J346<>"",J346,IFERROR(VLOOKUP(H346,PointsSystem!$A$2:$B$21,2,FALSE),0))) -> 12
E347: =IF(OR(A347="",B347="",C347="",D347=""),"",IFERROR(INDEX(Races!$E$2:$E$1000,MATCH(A347&"|"&B347&"|"&C347&"|"&D347, Races!$H$2:$H$1000, 0)),"")) | H347: 5 | I347: =IF(H347="","",IF(J347<>"",J347,IFERROR(VLOOKUP(H347,PointsSystem!$A$2:$B$21,2,FALSE),0))) -> 10
E348: =IF(OR(A348="",B348="",C348="",D348=""),"",IFERROR(INDEX(Races!$E$2:$E$1000,MATCH(A348&"|"&B348&"|"&C348&"|"&D348, Races!$H$2:$H$1000, 0)),"")) | H348: 6 | I348: =IF(H348="","",IF(J348<>"",J348,IFERROR(VLOOKUP(H348,PointsSystem!$A$2:$B$21,2,FALSE),0))) -> 8
E349: =IF(OR(A349="",B349="",C349="",D349=""),"",IFERROR(INDEX(Races!$E$2:$E$1000,MATCH(A349&"|"&B349&"|"&C349&"|"&D349, Races!$H$2:$H$1000, 0)),"")) | H349: 7 | I349: =IF(H349="","",IF(J349<>"",J349,IFERROR(VLOOKUP(H349,PointsSystem!$A$2:$B$21,2,FALSE),0))) -> 6
E350: =IF(OR(A350="",B350="",C350="",D350=""),"",IFERROR(INDEX(Races!$E$2:$E$1000,MATCH(A350&"|"&B350&"|"&C350&"|"&D350, Races!$H$2:$H$1000, 0)),"")) | H350: 8 | I350: =IF(H350="","",IF(J350<>"",J350,IFERROR(VLOOKUP(H350,PointsSystem!$A$2:$B$21,2,FALSE),0))) -> 4
...

Sheet Standings
A1: Standings Filters
A2: Game: | B2: F1 25 | E2: Change filters in B2/B3/B4
A3: Season: | B3: 2026
A4: League: | B4: 100 por cento
A6: Driver | B6: Total Points (filtered) | C6: Races Counted | D6: Avg Points
A7: =Drivers!A2 -> TomasRodri21 | B7: =IF($A7="","",SUMIFS(PointsEntry!$I$2:$I$5000,PointsEntry!$F$2:$F$5000,$A7,PointsEntry!$A$2:$A$5000,$B$2,PointsEntry!$B$2:$B$5000,$B$3,PointsEntry!$C$2:$C$5000,$B$4)) -> 118 | C7: =IF($A7="","",COUNTIFS(PointsEntry!$F$2:$F$5000,$A7,PointsEntry!$A$2:$A$5000,$B$2,PointsEntry!$B$2:$B$5000,$B$3,PointsEntry!$C$2:$C$5000,$B$4)) -> 7 | D7: =IF($C7="","",IFERROR($B7/$C7,0)) -> 16.857143
A8: =Drivers!A3 -> Polingua | B8: =IF($A8="","",SUMIFS(PointsEntry!$I$2:$I$5000,PointsEntry!$F$2:$F$5000,$A8,PointsEntry!$A$2:$A$5000,$B$2,PointsEntry!$B$2:$B$5000,$B$3,PointsEntry!$C$2:$C$5000,$B$4)) -> 67 | C8: =IF($A8="","",COUNTIFS(PointsEntry!$F$2:$F$5000,$A8,PointsEntry!$A$2:$A$5000,$B$2,PointsEntry!$B$2:$B$5000,$B$3,PointsEntry!$C$2:$C$5000,$B$4)) -> 7 | D8: =IF($C8="","",IFERROR($B8/$C8,0)) -> 9.5714286
A9: =Drivers!A6 -> Max Verstappen | B9: =IF($A9="","",SUMIFS(PointsEntry!$I$2:$I$5000,PointsEntry!$F$2:$F$5000,$A9,PointsEntry!$A$2:$A$5000,$B$2,PointsEntry!$B$2:$B$5000,$B$3,PointsEntry!$C$2:$C$5000,$B$4)) -> 83 | C9: =IF($A9="","",COUNTIFS(PointsEntry!$F$2:$F$5000,$A9,PointsEntry!$A$2:$A$5000,$B$2,PointsEntry!$B$2:$B$5000,$B$3,PointsEntry!$C$2:$C$5000,$B$4)) -> 7 | D9: =IF($C9="","",IFERROR($B9/$C9,0)) -> 11.857143
A10: =Drivers!A8 -> Lando Norris | B10: =IF($A10="","",SUMIFS(PointsEntry!$I$2:$I$5000,PointsEntry!$F$2:$F$5000,$A10,PointsEntry!$A$2:$A$5000,$B$2,PointsEntry!$B$2:$B$5000,$B$3,PointsEntry!$C$2:$C$5000,$B$4)) -> 72 | C10: =IF($A10="","",COUNTIFS(PointsEntry!$F$2:$F$5000,$A10,PointsEntry!$A$2:$A$5000,$B$2,PointsEntry!$B$2:$B$5000,$B$3,PointsEntry!$C$2:$C$5000,$B$4)) -> 7 | D10: =IF($C10="","",IFERROR($B10/$C10,0)) -> 10.285714
A11: =Drivers!A9 -> George Russell | B11: =IF($A11="","",SUMIFS(PointsEntry!$I$2:$I$5000,PointsEntry!$F$2:$F$5000,$A11,PointsEntry!$A$2:$A$5000,$B$2,PointsEntry!$B$2:$B$5000,$B$3,PointsEntry!$C$2:$C$5000,$B$4)) -> 59 | C11: =IF($A11="","",COUNTIFS(PointsEntry!$F$2:$F$5000,$A11,PointsEntry!$A$2:$A$5000,$B$2,PointsEntry!$B$2:$B$5000,$B$3,PointsEntry!$C$2:$C$5000,$B$4)) -> 7 | D11: =IF($C11="","",IFERROR($B11/$C11,0)) -> 8.4285714
A12: =Drivers!A13 -> Oscar Piastri | B12: =IF($A12="","",SUMIFS(PointsEntry!$I$2:$I$5000,PointsEntry!$F$2:$F$5000,$A12,PointsEntry!$A$2:$A$5000,$B$2,PointsEntry!$B$2:$B$5000,$B$3,PointsEntry!$C$2:$C$5000,$B$4)) -> 54 | C12: =IF($A12="","",COUNTIFS(PointsEntry!$F$2:$F$5000,$A12,PointsEntry!$A$2:$A$5000,$B$2,PointsEntry!$B$2:$B$5000,$B$3,PointsEntry!$C$2:$C$5000,$B$4)) -> 7 | D12: =IF($C12="","",IFERROR($B12/$C12,0)) -> 7.7142857
A13: =Drivers!A5 -> Lewis Hamilton | B13: =IF($A13="","",SUMIFS(PointsEntry!$I$2:$I$5000,PointsEntry!$F$2:$F$5000,$A13,PointsEntry!$A$2:$A$5000,$B$2,PointsEntry!$B$2:$B$5000,$B$3,PointsEntry!$C$2:$C$5000,$B$4)) -> 50 | C13: =IF($A13="","",COUNTIFS(PointsEntry!$F$2:$F$5000,$A13,PointsEntry!$A$2:$A$5000,$B$2,PointsEntry!$B$2:$B$5000,$B$3,PointsEntry!$C$2:$C$5000,$B$4)) -> 7 | D13: =IF($C13="","",IFERROR($B13/$C13,0)) -> 7.1428571
A14: =Drivers!A12 -> Fernando Alonso | B14: =IF($A14="","",SUMIFS(PointsEntry!$I$2:$I$5000,PointsEntry!$F$2:$F$5000,$A14,PointsEntry!$A$2:$A$5000,$B$2,PointsEntry!$B$2:$B$5000,$B$3,PointsEntry!$C$2:$C$5000,$B$4)) -> 44 | C14: =IF($A14="","",COUNTIFS(PointsEntry!$F$2:$F$5000,$A14,PointsEntry!$A$2:$A$5000,$B$2,PointsEntry!$B$2:$B$5000,$B$3,PointsEntry!$C$2:$C$5000,$B$4)) -> 7 | D14: =IF($C14="","",IFERROR($B14/$C14,0)) -> 6.2857143
A15: =Drivers!A4 -> Fatacuida | B15: =IF($A15="","",SUMIFS(PointsEntry!$I$2:$I$5000,PointsEntry!$F$2:$F$5000,$A15,PointsEntry!$A$2:$A$5000,$B$2,PointsEntry!$B$2:$B$5000,$B$3,PointsEntry!$C$2:$C$5000,$B$4)) -> 37 | C15: =IF($A15="","",COUNTIFS(PointsEntry!$F$2:$F$5000,$A15,PointsEntry!$A$2:$A$5000,$B$2,PointsEntry!$B$2:$B$5000,$B$3,PointsEntry!$C$2:$C$5000,$B$4)) -> 7 | D15: =IF($C15="","",IFERROR($B15/$C15,0)) -> 5.2857143
A16: =Drivers!A7 -> Charles Leclerc | B16: =IF($A16="","",SUMIFS(PointsEntry!$I$2:$I$5000,PointsEntry!$F$2:$F$5000,$A16,PointsEntry!$A$2:$A$5000,$B$2,PointsEntry!$B$2:$B$5000,$B$3,PointsEntry!$C$2:$C$5000,$B$4)) -> 43 | C16: =IF($A16="","",COUNTIFS(PointsEntry!$F$2:$F$5000,$A16,PointsEntry!$A$2:$A$5000,$B$2,PointsEntry!$B$2:$B$5000,$B$3,PointsEntry!$C$2:$C$5000,$B$4)) -> 7 | D16: =IF($C16="","",IFERROR($B16/$C16,0)) -> 6.1428571
A17: =Drivers!A37 -> Gabriel Bortoleto | B17: =IF($A17="","",SUMIFS(PointsEntry!$I$2:$I$5000,PointsEntry!$F$2:$F$5000,$A17,PointsEntry!$A$2:$A$5000,$B$2,PointsEntry!$B$2:$B$5000,$B$3,PointsEntry!$C$2:$C$5000,$B$4)) -> 27 | C17: =IF($A17="","",COUNTIFS(PointsEntry!$F$2:$F$5000,$A17,PointsEntry!$A$2:$A$5000,$B$2,PointsEntry!$B$2:$B$5000,$B$3,PointsEntry!$C$2:$C$5000,$B$4)) -> 7 | D17: =IF($C17="","",IFERROR($B17/$C17,0)) -> 3.8571429
A18: =Drivers!A10 -> Carlos Sainz Jr. | B18: =IF($A18="","",SUMIFS(PointsEntry!$I$2:$I$5000,PointsEntry!$F$2:$F$5000,$A18,PointsEntry!$A$2:$A$5000,$B$2,PointsEntry!$B$2:$B$5000,$B$3,PointsEntry!$C$2:$C$5000,$B$4)) -> 17 | C18: =IF($A18="","",COUNTIFS(PointsEntry!$F$2:$F$5000,$A18,PointsEntry!$A$2:$A$5000,$B$2,PointsEntry!$B$2:$B$5000,$B$3,PointsEntry!$C$2:$C$5000,$B$4)) -> 7 | D18: =IF($C18="","",IFERROR($B18/$C18,0)) -> 2.4285714
A19: =Drivers!A15 -> Esteban Ocon | B19: =IF($A19="","",SUMIFS(PointsEntry!$I$2:$I$5000,PointsEntry!$F$2:$F$5000,$A19,PointsEntry!$A$2:$A$5000,$B$2,PointsEntry!$B$2:$B$5000,$B$3,PointsEntry!$C$2:$C$5000,$B$4)) -> 14 | C19: =IF($A19="","",COUNTIFS(PointsEntry!$F$2:$F$5000,$A19,PointsEntry!$A$2:$A$5000,$B$2,PointsEntry!$B$2:$B$5000,$B$3,PointsEntry!$C$2:$C$5000,$B$4)) -> 7 | D19: =IF($C19="","",IFERROR($B19/$C19,0)) -> 2
A20: =Drivers!A20 -> Alexander Albon | B20: =IF($A20="","",SUMIFS(PointsEntry!$I$2:$I$5000,PointsEntry!$F$2:$F$5000,$A20,PointsEntry!$A$2:$A$5000,$B$2,PointsEntry!$B$2:$B$5000,$B$3,PointsEntry!$C$2:$C$5000,$B$4)) -> 8 | C20: =IF($A20="","",COUNTIFS(PointsEntry!$F$2:$F$5000,$A20,PointsEntry!$A$2:$A$5000,$B$2,PointsEntry!$B$2:$B$5000,$B$3,PointsEntry!$C$2:$C$5000,$B$4)) -> 7 | D20: =IF($C20="","",IFERROR($B20/$C20,0)) -> 1.1428571
A21: =Drivers!A14 -> Pierre Gasly | B21: =IF($A21="","",SUMIFS(PointsEntry!$I$2:$I$5000,PointsEntry!$F$2:$F$5000,$A21,PointsEntry!$A$2:$A$5000,$B$2,PointsEntry!$B$2:$B$5000,$B$3,PointsEntry!$C$2:$C$5000,$B$4)) -> 7 | C21: =IF($A21="","",COUNTIFS(PointsEntry!$F$2:$F$5000,$A21,PointsEntry!$A$2:$A$5000,$B$2,PointsEntry!$B$2:$B$5000,$B$3,PointsEntry!$C$2:$C$5000,$B$4)) -> 7 | D21: =IF($C21="","",IFERROR($B21/$C21,0)) -> 1
A22: =Drivers!A35 -> Oliver Bearman | B22: =IF($A22="","",SUMIFS(PointsEntry!$I$2:$I$5000,PointsEntry!$F$2:$F$5000,$A22,PointsEntry!$A$2:$A$5000,$B$2,PointsEntry!$B$2:$B$5000,$B$3,PointsEntry!$C$2:$C$5000,$B$4)) -> 2 | C22: =IF($A22="","",COUNTIFS(PointsEntry!$F$2:$F$5000,$A22,PointsEntry!$A$2:$A$5000,$B$2,PointsEntry!$B$2:$B$5000,$B$3,PointsEntry!$C$2:$C$5000,$B$4)) -> 7 | D22: =IF($C22="","",IFERROR($B22/$C22,0)) -> 0.28571429
A23: =Drivers!A18 -> Nico Hülkenberg | B23: =IF($A23="","",SUMIFS(PointsEntry!$I$2:$I$5000,PointsEntry!$F$2:$F$5000,$A23,PointsEntry!$A$2:$A$5000,$B$2,PointsEntry!$B$2:$B$5000,$B$3,PointsEntry!$C$2:$C$5000,$B$4)) -> 2 | C23: =IF($A23="","",COUNTIFS(PointsEntry!$F$2:$F$5000,$A23,PointsEntry!$A$2:$A$5000,$B$2,PointsEntry!$B$2:$B$5000,$B$3,PointsEntry!$C$2:$C$5000,$B$4)) -> 7 | D23: =IF($C23="","",IFERROR($B23/$C23,0)) -> 0.28571429
A24: =Drivers!A34 -> Liam Lawson | B24: =IF($A24="","",SUMIFS(PointsEntry!$I$2:$I$5000,PointsEntry!$F$2:$F$5000,$A24,PointsEntry!$A$2:$A$5000,$B$2,PointsEntry!$B$2:$B$5000,$B$3,PointsEntry!$C$2:$C$5000,$B$4)) -> 1 | C24: =IF($A24="","",COUNTIFS(PointsEntry!$F$2:$F$5000,$A24,PointsEntry!$A$2:$A$5000,$B$2,PointsEntry!$B$2:$B$5000,$B$3,PointsEntry!$C$2:$C$5000,$B$4)) -> 7 | D24: =IF($C24="","",IFERROR($B24/$C24,0)) -> 0.14285714
A25: =Drivers!A11 -> Sergio Pérez | B25: =IF($A25="","",SUMIFS(PointsEntry!$I$2:$I$5000,PointsEntry!$F$2:$F$5000,$A25,PointsEntry!$A$2:$A$5000,$B$2,PointsEntry!$B$2:$B$5000,$B$3,PointsEntry!$C$2:$C$5000,$B$4)) -> 0 | C25: =IF($A25="","",COUNTIFS(PointsEntry!$F$2:$F$5000,$A25,PointsEntry!$A$2:$A$5000,$B$2,PointsEntry!$B$2:$B$5000,$B$3,PointsEntry!$C$2:$C$5000,$B$4)) -> 0 | D25: =IF($C25="","",IFERROR($B25/$C25,0)) -> 0
A26: =Drivers!A16 -> Yuki Tsunoda | B26: =IF($A26="","",SUMIFS(PointsEntry!$I$2:$I$5000,PointsEntry!$F$2:$F$5000,$A26,PointsEntry!$A$2:$A$5000,$B$2,PointsEntry!$B$2:$B$5000,$B$3,PointsEntry!$C$2:$C$5000,$B$4)) -> 0 | C26: =IF($A26="","",COUNTIFS(PointsEntry!$F$2:$F$5000,$A26,PointsEntry!$A$2:$A$5000,$B$2,PointsEntry!$B$2:$B$5000,$B$3,PointsEntry!$C$2:$C$5000,$B$4)) -> 0 | D26: =IF($C26="","",IFERROR($B26/$C26,0)) -> 0
A27: =Drivers!A17 -> Valtteri Bottas | B27: =IF($A27="","",SUMIFS(PointsEntry!$I$2:$I$5000,PointsEntry!$F$2:$F$5000,$A27,PointsEntry!$A$2:$A$5000,$B$2,PointsEntry!$B$2:$B$5000,$B$3,PointsEntry!$C$2:$C$5000,$B$4)) -> 0 | C27: =IF($A27="","",COUNTIFS(PointsEntry!$F$2:$F$5000,$A27,PointsEntry!$A$2:$A$5000,$B$2,PointsEntry!$B$2:$B$5000,$B$3,PointsEntry!$C$2:$C$5000,$B$4)) -> 0 | D27: =IF($C27="","",IFERROR($B27/$C27,0)) -> 0
A28: =Drivers!A19 -> Lance Stroll | B28: =IF($A28="","",SUMIFS(PointsEntry!$I$2:$I$5000,PointsEntry!$F$2:$F$5000,$A28,PointsEntry!$A$2:$A$5000,$B$2,PointsEntry!$B$2:$B$5000,$B$3,PointsEntry!$C$2:$C$5000,$B$4)) -> 0 | C28: =IF($A28="","",COUNTIFS(PointsEntry!$F$2:$F$5000,$A28,PointsEntry!$A$2:$A$5000,$B$2,PointsEntry!$B$2:$B$5000,$B$3,PointsEntry!$C$2:$C$5000,$B$4)) -> 7 | D28: =IF($C28="","",IFERROR($B28/$C28,0)) -> 0
A29: =Drivers!A21 -> Kevin Magnussen | B29: =IF($A29="","",SUMIFS(PointsEntry!$I$2:$I$5000,PointsEntry!$F$2:$F$5000,$A29,PointsEntry!$A$2:$A$5000,$B$2,PointsEntry!$B$2:$B$5000,$B$3,PointsEntry!$C$2:$C$5000,$B$4)) -> 0 | C29: =IF($A29="","",COUNTIFS(PointsEntry!$F$2:$F$5000,$A29,PointsEntry!$A$2:$A$5000,$B$2,PointsEntry!$B$2:$B$5000,$B$3,PointsEntry!$C$2:$C$5000,$B$4)) -> 0 | D29: =IF($C29="","",IFERROR($B29/$C29,0)) -> 0
A30: =Drivers!A22 -> Daniel Ricciardo | B30: =IF($A30="","",SUMIFS(PointsEntry!$I$2:$I$5000,PointsEntry!$F$2:$F$5000,$A30,PointsEntry!$A$2:$A$5000,$B$2,PointsEntry!$B$2:$B$5000,$B$3,PointsEntry!$C$2:$C$5000,$B$4)) -> 0 | C30: =IF($A30="","",COUNTIFS(PointsEntry!$F$2:$F$5000,$A30,PointsEntry!$A$2:$A$5000,$B$2,PointsEntry!$B$2:$B$5000,$B$3,PointsEntry!$C$2:$C$5000,$B$4)) -> 0 | D30: =IF($C30="","",IFERROR($B30/$C30,0)) -> 0
A31: =Drivers!A23 -> Sebastian Vettel | B31: =IF($A31="","",SUMIFS(PointsEntry!$I$2:$I$5000,PointsEntry!$F$2:$F$5000,$A31,PointsEntry!$A$2:$A$5000,$B$2,PointsEntry!$B$2:$B$5000,$B$3,PointsEntry!$C$2:$C$5000,$B$4)) -> 0 | C31: =IF($A31="","",COUNTIFS(PointsEntry!$F$2:$F$5000,$A31,PointsEntry!$A$2:$A$5000,$B$2,PointsEntry!$B$2:$B$5000,$B$3,PointsEntry!$C$2:$C$5000,$B$4)) -> 0 | D31: =IF($C31="","",IFERROR($B31/$C31,0)) -> 0
A32: =Drivers!A24 -> Kimi Räikkönen | B32: =IF($A32="","",SUMIFS(PointsEntry!$I$2:$I$5000,PointsEntry!$F$2:$F$5000,$A32,PointsEntry!$A$2:$A$5000,$B$2,PointsEntry!$B$2:$B$5000,$B$3,PointsEntry!$C$2:$C$5000,$B$4)) -> 0 | C32: =IF($A32="","",COUNTIFS(PointsEntry!$F$2:$F$5000,$A32,PointsEntry!$A$2:$A$5000,$B$2,PointsEntry!$B$2:$B$5000,$B$3,PointsEntry!$C$2:$C$5000,$B$4)) -> 0 | D32: =IF($C32="","",IFERROR($B32/$C32,0)) -> 0
A33: =Drivers!A25 -> Antonio Giovinazzi | B33: =IF($A33="","",SUMIFS(PointsEntry!$I$2:$I$5000,PointsEntry!$F$2:$F$5000,$A33,PointsEntry!$A$2:$A$5000,$B$2,PointsEntry!$B$2:$B$5000,$B$3,PointsEntry!$C$2:$C$5000,$B$4)) -> 0 | C33: =IF($A33="","",COUNTIFS(PointsEntry!$F$2:$F$5000,$A33,PointsEntry!$A$2:$A$5000,$B$2,PointsEntry!$B$2:$B$5000,$B$3,PointsEntry!$C$2:$C$5000,$B$4)) -> 0 | D33: =IF($C33="","",IFERROR($B33/$C33,0)) -> 0
A34: =Drivers!A26 -> Romain Grosjean | B34: =IF($A34="","",SUMIFS(PointsEntry!$I$2:$I$5000,PointsEntry!$F$2:$F$5000,$A34,PointsEntry!$A$2:$A$5000,$B$2,PointsEntry!$B$2:$B$5000,$B$3,PointsEntry!$C$2:$C$5000,$B$4)) -> 0 | C34: =IF($A34="","",COUNTIFS(PointsEntry!$F$2:$F$5000,$A34,PointsEntry!$A$2:$A$5000,$B$2,PointsEntry!$B$2:$B$5000,$B$3,PointsEntry!$C$2:$C$5000,$B$4)) -> 0 | D34: =IF($C34="","",IFERROR($B34/$C34,0)) -> 0
A35: =Drivers!A27 -> Robert Kubica | B35: =IF($A35="","",SUMIFS(PointsEntry!$I$2:$I$5000,PointsEntry!$F$2:$F$5000,$A35,PointsEntry!$A$2:$A$5000,$B$2,PointsEntry!$B$2:$B$5000,$B$3,PointsEntry!$C$2:$C$5000,$B$4)) -> 0 | C35: =IF($A35="","",COUNTIFS(PointsEntry!$F$2:$F$5000,$A35,PointsEntry!$A$2:$A$5000,$B$2,PointsEntry!$B$2:$B$5000,$B$3,PointsEntry!$C$2:$C$5000,$B$4)) -> 0 | D35: =IF($C35="","",IFERROR($B35/$C35,0)) -> 0
A36: =Drivers!A28 -> Nicholas Latifi | B36: =IF($A36="","",SUMIFS(PointsEntry!$I$2:$I$5000,PointsEntry!$F$2:$F$5000,$A36,PointsEntry!$A$2:$A$5000,$B$2,PointsEntry!$B$2:$B$5000,$B$3,PointsEntry!$C$2:$C$5000,$B$4)) -> 0 | C36: =IF($A36="","",COUNTIFS(PointsEntry!$F$2:$F$5000,$A36,PointsEntry!$A$2:$A$5000,$B$2,PointsEntry!$B$2:$B$5000,$B$3,PointsEntry!$C$2:$C$5000,$B$4)) -> 0 | D36: =IF($C36="","",IFERROR($B36/$C36,0)) -> 0
A37: =Drivers!A29 -> Mick Schumacher | B37: =IF($A37="","",SUMIFS(PointsEntry!$I$2:$I$5000,PointsEntry!$F$2:$F$5000,$A37,PointsEntry!$A$2:$A$5000,$B$2,PointsEntry!$B$2:$B$5000,$B$3,PointsEntry!$C$2:$C$5000,$B$4)) -> 0 | C37: =IF($A37="","",COUNTIFS(PointsEntry!$F$2:$F$5000,$A37,PointsEntry!$A$2:$A$5000,$B$2,PointsEntry!$B$2:$B$5000,$B$3,PointsEntry!$C$2:$C$5000,$B$4)) -> 0 | D37: =IF($C37="","",IFERROR($B37/$C37,0)) -> 0
A38: =Drivers!A30 -> Nikita Mazepin | B38: =IF($A38="","",SUMIFS(PointsEntry!$I$2:$I$5000,PointsEntry!$F$2:$F$5000,$A38,PointsEntry!$A$2:$A$5000,$B$2,PointsEntry!$B$2:$B$5000,$B$3,PointsEntry!$C$2:$C$5000,$B$4)) -> 0 | C38: =IF($A38="","",COUNTIFS(PointsEntry!$F$2:$F$5000,$A38,PointsEntry!$A$2:$A$5000,$B$2,PointsEntry!$B$2:$B$5000,$B$3,PointsEntry!$C$2:$C$5000,$B$4)) -> 0 | D38: =IF($C38="","",IFERROR($B38/$C38,0)) -> 0
A39: =Drivers!A31 -> Zhou Guanyu | B39: =IF($A39="","",SUMIFS(PointsEntry!$I$2:$I$5000,PointsEntry!$F$2:$F$5000,$A39,PointsEntry!$A$2:$A$5000,$B$2,PointsEntry!$B$2:$B$5000,$B$3,PointsEntry!$C$2:$C$5000,$B$4)) -> 0 | C39: =IF($A39="","",COUNTIFS(PointsEntry!$F$2:$F$5000,$A39,PointsEntry!$A$2:$A$5000,$B$2,PointsEntry!$B$2:$B$5000,$B$3,PointsEntry!$C$2:$C$5000,$B$4)) -> 0 | D39: =IF($C39="","",IFERROR($B39/$C39,0)) -> 0
A40: =Drivers!A32 -> Logan Sargeant | B40: =IF($A40="","",SUMIFS(PointsEntry!$I$2:$I$5000,PointsEntry!$F$2:$F$5000,$A40,PointsEntry!$A$2:$A$5000,$B$2,PointsEntry!$B$2:$B$5000,$B$3,PointsEntry!$C$2:$C$5000,$B$4)) -> 0 | C40: =IF($A40="","",COUNTIFS(PointsEntry!$F$2:$F$5000,$A40,PointsEntry!$A$2:$A$5000,$B$2,PointsEntry!$B$2:$B$5000,$B$3,PointsEntry!$C$2:$C$5000,$B$4)) -> 0 | D40: =IF($C40="","",IFERROR($B40/$C40,0)) -> 0
A41: =Drivers!A33 -> Nyck de Vries | B41: =IF($A41="","",SUMIFS(PointsEntry!$I$2:$I$5000,PointsEntry!$F$2:$F$5000,$A41,PointsEntry!$A$2:$A$5000,$B$2,PointsEntry!$B$2:$B$5000,$B$3,PointsEntry!$C$2:$C$5000,$B$4)) -> 0 | C41: =IF($A41="","",COUNTIFS(PointsEntry!$F$2:$F$5000,$A41,PointsEntry!$A$2:$A$5000,$B$2,PointsEntry!$B$2:$B$5000,$B$3,PointsEntry!$C$2:$C$5000,$B$4)) -> 0 | D41: =IF($C41="","",IFERROR($B41/$C41,0)) -> 0
...
